import test from 'ava';
import avaRuleTester from 'eslint-ava-rule-tester';
import {outdent} from 'outdent';
import rule from '../rules/catch-error-name';

const ruleTester = avaRuleTester(test, {
	parserOptions: {
		ecmaVersion: 2020
	}
});

const typescriptRuleTester = avaRuleTester(test, {
	parser: require.resolve('@typescript-eslint/parser')
});

function invalidTestCase(options) {
	if (typeof options === 'string') {
		options = {code: options};
	}

	const {code, name, output} = options;
	return {
		code,
		output: output || code,
		options: name ? [{name}] : [],
		errors: [{ruleId: 'catch-error-name'}]
	};
}

ruleTester.run('catch-error-name', rule, {
	valid: [
		'try {} catch (error) {}',
		'try {} catch (_) {}',
		'try {} catch (_) { console.log(foo); }',
		{
			code: 'try {} catch (err) {}',
			options: [{name: 'err'}]
		},
		outdent`
			try {
			} catch (outerError) {
				try {
				} catch (innerError) {}
			}
		`,
		outdent`
			const handleError = error => {
				try {
					doSomething();
				} catch (error_) {
					console.log(error_);
				}
			}
		`,
		{
			code: outdent`
				const handleError = err => {
					try {
						doSomething();
					} catch (err_) {
						console.log(err_);
					}
				}
			`,
			options: [{name: 'err'}]
		},
		outdent`
			const handleError = error => {
				const error_ = new Error('ðŸ¦„');

				try {
					doSomething();
				} catch (error__) {
					console.log(error__);
				}
			}
		`,
		'obj.catch(error => {})',
		outdent`
			const handleError = error => {
				obj.catch(error_ => { });
			}
		`,
		{
			code: outdent`
				const handleError = err => {
					obj.catch(err_ => { });
				}
			`,
			options: [{name: 'err'}]
		},
		outdent`
			const handleError = error => {
				const error_ = new Error('foo bar');

				obj.catch(error__ => { });
			}
		`,
		outdent`
			const handleError = error => {
				const error_ = new Error('foo bar');
				const error__ = new Error('foo bar');
				const error___ = new Error('foo bar');
				const error____ = new Error('foo bar');
				const error_____ = new Error('foo bar');
				const error______ = new Error('foo bar');
				const error_______ = new Error('foo bar');
				const error________ = new Error('foo bar');
				const error_________ = new Error('foo bar');

				obj.catch(error__________ => { });
			}
		`,
		'obj.catch(() => {})',
		'obj.catch((_) => {})',
		'obj.catch((_) => { console.log(foo); })',
		{
			code: 'obj.catch(err => {})',
			options: [{name: 'err'}]
		},
		outdent`
			obj.catch(
				outerError => {
					return obj2.catch(innerError => {})
				}
			)
		`,
		'obj.catch(function (error) {})',
		'obj.catch(function () {})',
		{
			code: 'obj.catch(function (err) {})',
			options: [{name: 'err'}]
		},
		outdent`
			obj.catch(function (outerError) {
				return obj2.catch(function (innerError) {
				})
			})
		`,
		'obj.catch()',
		'obj.catch(_ => { console.log(_); })',
		'obj.catch(function (_) { console.log(_); })',
		'foo(function (error) {})',
		'foo().then(function (error) {})',
		'foo().catch(function (error) {})',
		'try {} catch (_) {}',
		outdent`
			try {
			} catch (_) {
				try {
				} catch (_) {}
			}
		`,
		'try {} catch (_) { console.log(_); }',
		outdent`
				const handleError = error => {
					try {
						doSomething();
					} catch (_) {
						console.log(_);
					}
				}
		`,
		'obj.catch(_ => {})',
		{
			code: 'try {} catch (skipErr) {}',
			options: [
				{
					caughtErrorsIgnorePattern: '^skip'
				}
			]
		},
		outdent`
			try {
				throw new Error('message');
			} catch {
				console.log('failed');
			}
		`,
		'try {} catch (descriptiveError) {}',
		'try {} catch (descriptiveerror) {}'
	],

	invalid: [
		invalidTestCase({
			code: outdent`
				try {
				} catch (err) {
					console.log(err)
				}
			`,
			output: outdent`
				try {
				} catch (error) {
					console.log(error)
				}
			`
		}),
		invalidTestCase({
			code: outdent`
				try {
				} catch (error) {
					console.log(error)
				}
			`,
			output: outdent`
				try {
				} catch (err) {
					console.log(err)
				}
			`,
			name: 'err'
		}),
		invalidTestCase('try {} catch ({message}) {}'),
		{
			code: 'try {} catch (outerError) {}',
			output: 'try {} catch (error) {}',
			errors: [
				{
					ruleId: 'catch-error-message',
					message: 'The catch parameter should be named `error`.'
				}
			],
			options: [
				{
					caughtErrorsIgnorePattern: '^_$'
				}
			]
		},
		{
			code: 'try {} catch (innerError) {}',
			output: 'try {} catch (error) {}',
			errors: [
				{
					ruleId: 'catch-error-name',
					message: 'The catch parameter should be named `error`.'
				}
			],
			options: [
				{
					caughtErrorsIgnorePattern: '^_$'
				}
			]
		},
		invalidTestCase({
			code: 'obj.catch(err => err)',
			output: 'obj.catch(error => error)'
		}),
		invalidTestCase({
			code: 'obj.catch(error => error.stack)',
			output: 'obj.catch(err => err.stack)',
			name: 'err'
		}),
		invalidTestCase('obj.catch(({message}) => {})'),
		invalidTestCase({
			code: outdent`
				obj.catch(function (err) {
					console.log(err)
				})
			`,
			output: outdent`
				obj.catch(function (error) {
					console.log(error)
				})
			`
		}),
		invalidTestCase('obj.catch(function ({message}) {})'),
		invalidTestCase({
			code: outdent`
				obj.catch(function (error) {
					console.log(error)
				})
			`,
			output: outdent`
				obj.catch(function (err) {
					console.log(err)
				})
			`,
			name: 'err'
		}),
		// Failing tests for #107
		// invalidTestCase(outdent`
		// 	foo.then(() => {
		// 		try {} catch (e) {}
		// 	}).catch(error => error);
		// `),
		// invalidTestCase(outdent`
		// 	foo.then(() => {
		// 		try {} catch (e) {}
		// 	});
		// `),
		{
			code: outdent`
				const handleError = error => {
					try {
						doSomething();
					} catch (foo) {
						console.log(foo);
					}
				}
			`,
			output: outdent`
				const handleError = error => {
					try {
						doSomething();
					} catch (error_) {
						console.log(error_);
					}
				}
			`,
			errors: [
				{
					ruleId: 'catch-error-name',
					message: 'The catch parameter should be named `error_`.'
				}
			]
		},
		{
			code: outdent`
				const handleError = error => {
					try {
						doSomething();
					} catch (error2) {
						console.log(error2);
					}
				}
			`,
			output: outdent`
				const handleError = error => {
					try {
						doSomething();
					} catch (error_) {
						console.log(error_);
					}
				}
			`,
			errors: [
				{
					ruleId: 'catch-error-name',
					message: 'The catch parameter should be named `error_`.'
				}
			],
			options: [
				{
					caughtErrorsIgnorePattern: '^_$'
				}
			]
		},
		{
			code: outdent`
				const handleError = error => {
					const error9 = new Error('foo bar');

					try {
						doSomething();
					} catch (foo) {
						console.log(foo);
					}
				}
			`,
			output: outdent`
				const handleError = error => {
					const error9 = new Error('foo bar');

					try {
						doSomething();
					} catch (error_) {
						console.log(error_);
					}
				}
			`,
			errors: [
				{
					ruleId: 'catch-error-name',
					message: 'The catch parameter should be named `error_`.'
				}
			]
		},
		{
			code: outdent`
				const handleError = error => {
					const error_ = new Error('foo bar');

					obj.catch(foo => { });
				}
			`,
			output: outdent`
				const handleError = error => {
					const error_ = new Error('foo bar');

					obj.catch(error__ => { });
				}
			`,
			errors: [
				{
					ruleId: 'catch-error-name',
					message: 'The catch parameter should be named `error__`.'
				}
			]
		},
		{
			code: outdent`
				const handleError = error => {
					const error_ = new Error('foo bar');

					obj.catch(foo => { });
				}
			`,
			output: outdent`
				const handleError = error => {
					const error_ = new Error('foo bar');

					obj.catch(error__ => { });
				}
			`,
			errors: [
				{
					ruleId: 'catch-error-name',
					message: 'The catch parameter should be named `error__`.'
				}
			],
			options: [
				{
					name: 'error'
				}
			]
		},
		{
			code: outdent`
				obj.catch(err => {});
				obj.catch(err => {});
			`,
			output: outdent`
				obj.catch(error => {});
				obj.catch(error => {});
			`,
			errors: [{ruleId: 'catch-error-name'}, {ruleId: 'catch-error-name'}]
		},
		{
			code: 'try {} catch (_error) {}',
			output: 'try {} catch (error) {}',
			errors: [
				{
					ruleId: 'catch-error-name',
					message: 'The catch parameter should be named `error`.'
				}
			],
			options: [
				{
					caughtErrorsIgnorePattern: '^skip'
				}
			]
		},
		{
			code: outdent`
				Promise.reject(new Error())
					.catch(function onError(errorResult) {
						console.log('errorResult should be fixed to', errorResult)
					})
			`,
			output: outdent`
				Promise.reject(new Error())
					.catch(function onError(error) {
						console.log('errorResult should be fixed to', error)
					})
			`,
			errors: [
				{
					ruleId: 'catch-error-message',
					message: 'The catch parameter should be named `error`.'
				}
			],
			options: [
				{
					caughtErrorsIgnorePattern: '^_$'
				}
			]
		}
	]
});

typescriptRuleTester.run('catch-error-name', rule, {
	valid: [],
	invalid: [
		invalidTestCase({
			code: outdent`
				promise.catch(function (err: Error) {
					console.log(err)
				})
			`,
			output: outdent`
				promise.catch(function (error: Error) {
					console.log(error)
				})
			`
		})
	]
});
